[2024-02-21 05:36:09,983] {taskinstance.py:1159} INFO - Dependencies all met for <TaskInstance: csv_transformation_and_class_creation.create_class_task manual__2024-02-21T05:31:06.916236+00:00 [queued]>
[2024-02-21 05:36:09,992] {taskinstance.py:1159} INFO - Dependencies all met for <TaskInstance: csv_transformation_and_class_creation.create_class_task manual__2024-02-21T05:31:06.916236+00:00 [queued]>
[2024-02-21 05:36:09,993] {taskinstance.py:1356} INFO - 
--------------------------------------------------------------------------------
[2024-02-21 05:36:09,993] {taskinstance.py:1357} INFO - Starting attempt 2 of 2
[2024-02-21 05:36:09,993] {taskinstance.py:1358} INFO - 
--------------------------------------------------------------------------------
[2024-02-21 05:36:10,003] {taskinstance.py:1377} INFO - Executing <Task(BashOperator): create_class_task> on 2024-02-21 05:31:06.916236+00:00
[2024-02-21 05:36:10,008] {standard_task_runner.py:52} INFO - Started process 2320 to run task
[2024-02-21 05:36:10,012] {standard_task_runner.py:79} INFO - Running: ['***', 'tasks', 'run', 'csv_transformation_and_class_creation', 'create_class_task', 'manual__2024-02-21T05:31:06.916236+00:00', '--job-id', '29', '--raw', '--subdir', 'DAGS_FOLDER/dags.py', '--cfg-path', '/tmp/tmp_dv5deam', '--error-file', '/tmp/tmptsb0687i']
[2024-02-21 05:36:10,013] {standard_task_runner.py:80} INFO - Job 29: Subtask create_class_task
[2024-02-21 05:36:10,058] {task_command.py:369} INFO - Running <TaskInstance: csv_transformation_and_class_creation.create_class_task manual__2024-02-21T05:31:06.916236+00:00 [running]> on host 7f99983bc7dc
[2024-02-21 05:36:10,109] {taskinstance.py:1571} INFO - Exporting the following env vars:
AIRFLOW_CTX_DAG_OWNER=***
AIRFLOW_CTX_DAG_ID=csv_transformation_and_class_creation
AIRFLOW_CTX_TASK_ID=create_class_task
AIRFLOW_CTX_EXECUTION_DATE=2024-02-21T05:31:06.916236+00:00
AIRFLOW_CTX_TRY_NUMBER=2
AIRFLOW_CTX_DAG_RUN_ID=manual__2024-02-21T05:31:06.916236+00:00
[2024-02-21 05:36:10,110] {subprocess.py:62} INFO - Tmp dir root location: 
 /tmp
[2024-02-21 05:36:10,111] {subprocess.py:74} INFO - Running command: ['bash', '-c', 'pytest']
[2024-02-21 05:36:10,117] {subprocess.py:85} INFO - Output:
[2024-02-21 05:36:10,119] {subprocess.py:92} INFO - bash: line 1: pytest: command not found
[2024-02-21 05:36:10,120] {subprocess.py:96} INFO - Command exited with return code 127
[2024-02-21 05:36:10,132] {taskinstance.py:1889} ERROR - Task failed with exception
Traceback (most recent call last):
  File "/home/airflow/.local/lib/python3.7/site-packages/airflow/operators/bash.py", line 195, in execute
    f'Bash command failed. The command returned a non-zero exit code {result.exit_code}.'
airflow.exceptions.AirflowException: Bash command failed. The command returned a non-zero exit code 127.
[2024-02-21 05:36:10,134] {taskinstance.py:1400} INFO - Marking task as FAILED. dag_id=csv_transformation_and_class_creation, task_id=create_class_task, execution_date=20240221T053106, start_date=20240221T053609, end_date=20240221T053610
[2024-02-21 05:36:10,143] {standard_task_runner.py:97} ERROR - Failed to execute job 29 for task create_class_task (Bash command failed. The command returned a non-zero exit code 127.; 2320)
[2024-02-21 05:36:10,154] {local_task_job.py:156} INFO - Task exited with return code 1
[2024-02-21 05:36:10,178] {local_task_job.py:273} INFO - 0 downstream tasks scheduled from follow-on schedule check
