[2024-02-21 05:06:07,846] {taskinstance.py:1159} INFO - Dependencies all met for <TaskInstance: csv_transformation_and_class_creation.transform_csv_task manual__2024-02-21T05:01:06.252006+00:00 [queued]>
[2024-02-21 05:06:07,855] {taskinstance.py:1159} INFO - Dependencies all met for <TaskInstance: csv_transformation_and_class_creation.transform_csv_task manual__2024-02-21T05:01:06.252006+00:00 [queued]>
[2024-02-21 05:06:07,856] {taskinstance.py:1356} INFO - 
--------------------------------------------------------------------------------
[2024-02-21 05:06:07,856] {taskinstance.py:1357} INFO - Starting attempt 2 of 2
[2024-02-21 05:06:07,856] {taskinstance.py:1358} INFO - 
--------------------------------------------------------------------------------
[2024-02-21 05:06:07,868] {taskinstance.py:1377} INFO - Executing <Task(PythonOperator): transform_csv_task> on 2024-02-21 05:01:06.252006+00:00
[2024-02-21 05:06:07,872] {standard_task_runner.py:52} INFO - Started process 874 to run task
[2024-02-21 05:06:07,876] {standard_task_runner.py:79} INFO - Running: ['***', 'tasks', 'run', 'csv_transformation_and_class_creation', 'transform_csv_task', 'manual__2024-02-21T05:01:06.252006+00:00', '--job-id', '12', '--raw', '--subdir', 'DAGS_FOLDER/dags.py', '--cfg-path', '/tmp/tmpz017qax6', '--error-file', '/tmp/tmpg0t9tzrk']
[2024-02-21 05:06:07,877] {standard_task_runner.py:80} INFO - Job 12: Subtask transform_csv_task
[2024-02-21 05:06:07,928] {task_command.py:369} INFO - Running <TaskInstance: csv_transformation_and_class_creation.transform_csv_task manual__2024-02-21T05:01:06.252006+00:00 [running]> on host 7f99983bc7dc
[2024-02-21 05:06:07,988] {taskinstance.py:1571} INFO - Exporting the following env vars:
AIRFLOW_CTX_DAG_OWNER=***
AIRFLOW_CTX_DAG_ID=csv_transformation_and_class_creation
AIRFLOW_CTX_TASK_ID=transform_csv_task
AIRFLOW_CTX_EXECUTION_DATE=2024-02-21T05:01:06.252006+00:00
AIRFLOW_CTX_TRY_NUMBER=2
AIRFLOW_CTX_DAG_RUN_ID=manual__2024-02-21T05:01:06.252006+00:00
[2024-02-21 05:06:08,250] {taskinstance.py:1889} ERROR - Task failed with exception
Traceback (most recent call last):
  File "/home/airflow/.local/lib/python3.7/site-packages/airflow/operators/python.py", line 171, in execute
    return_value = self.execute_callable()
  File "/home/airflow/.local/lib/python3.7/site-packages/airflow/operators/python.py", line 189, in execute_callable
    return self.python_callable(*self.op_args, **self.op_kwargs)
  File "/opt/airflow/dags/dags.py", line 36, in transform_csv
    df = pd.read_csv(input_path)
  File "/home/airflow/.local/lib/python3.7/site-packages/pandas/util/_decorators.py", line 311, in wrapper
    return func(*args, **kwargs)
  File "/home/airflow/.local/lib/python3.7/site-packages/pandas/io/parsers/readers.py", line 586, in read_csv
    return _read(filepath_or_buffer, kwds)
  File "/home/airflow/.local/lib/python3.7/site-packages/pandas/io/parsers/readers.py", line 482, in _read
    parser = TextFileReader(filepath_or_buffer, **kwds)
  File "/home/airflow/.local/lib/python3.7/site-packages/pandas/io/parsers/readers.py", line 811, in __init__
    self._engine = self._make_engine(self.engine)
  File "/home/airflow/.local/lib/python3.7/site-packages/pandas/io/parsers/readers.py", line 1040, in _make_engine
    return mapping[engine](self.f, **self.options)  # type: ignore[call-arg]
  File "/home/airflow/.local/lib/python3.7/site-packages/pandas/io/parsers/c_parser_wrapper.py", line 51, in __init__
    self._open_handles(src, kwds)
  File "/home/airflow/.local/lib/python3.7/site-packages/pandas/io/parsers/base_parser.py", line 229, in _open_handles
    errors=kwds.get("encoding_errors", "strict"),
  File "/home/airflow/.local/lib/python3.7/site-packages/pandas/io/common.py", line 707, in get_handle
    newline="",
FileNotFoundError: [Errno 2] No such file or directory: 'raw_content.csv'
[2024-02-21 05:06:08,258] {taskinstance.py:1400} INFO - Marking task as FAILED. dag_id=csv_transformation_and_class_creation, task_id=transform_csv_task, execution_date=20240221T050106, start_date=20240221T050607, end_date=20240221T050608
[2024-02-21 05:06:08,267] {standard_task_runner.py:97} ERROR - Failed to execute job 12 for task transform_csv_task ([Errno 2] No such file or directory: 'raw_content.csv'; 874)
[2024-02-21 05:06:08,308] {local_task_job.py:156} INFO - Task exited with return code 1
[2024-02-21 05:06:08,338] {local_task_job.py:273} INFO - 0 downstream tasks scheduled from follow-on schedule check
