[2024-02-21 05:48:23,458] {taskinstance.py:1159} INFO - Dependencies all met for <TaskInstance: csv_transformation_and_class_creation.create_class_task manual__2024-02-21T05:48:21.103638+00:00 [queued]>
[2024-02-21 05:48:23,477] {taskinstance.py:1159} INFO - Dependencies all met for <TaskInstance: csv_transformation_and_class_creation.create_class_task manual__2024-02-21T05:48:21.103638+00:00 [queued]>
[2024-02-21 05:48:23,478] {taskinstance.py:1356} INFO - 
--------------------------------------------------------------------------------
[2024-02-21 05:48:23,479] {taskinstance.py:1357} INFO - Starting attempt 1 of 2
[2024-02-21 05:48:23,479] {taskinstance.py:1358} INFO - 
--------------------------------------------------------------------------------
[2024-02-21 05:48:23,495] {taskinstance.py:1377} INFO - Executing <Task(BashOperator): create_class_task> on 2024-02-21 05:48:21.103638+00:00
[2024-02-21 05:48:23,499] {standard_task_runner.py:52} INFO - Started process 2904 to run task
[2024-02-21 05:48:23,503] {standard_task_runner.py:79} INFO - Running: ['***', 'tasks', 'run', 'csv_transformation_and_class_creation', 'create_class_task', 'manual__2024-02-21T05:48:21.103638+00:00', '--job-id', '37', '--raw', '--subdir', 'DAGS_FOLDER/dags.py', '--cfg-path', '/tmp/tmpe99io54y', '--error-file', '/tmp/tmpd98_k3fd']
[2024-02-21 05:48:23,504] {standard_task_runner.py:80} INFO - Job 37: Subtask create_class_task
[2024-02-21 05:48:23,552] {task_command.py:369} INFO - Running <TaskInstance: csv_transformation_and_class_creation.create_class_task manual__2024-02-21T05:48:21.103638+00:00 [running]> on host 7f99983bc7dc
[2024-02-21 05:48:23,612] {taskinstance.py:1571} INFO - Exporting the following env vars:
AIRFLOW_CTX_DAG_OWNER=***
AIRFLOW_CTX_DAG_ID=csv_transformation_and_class_creation
AIRFLOW_CTX_TASK_ID=create_class_task
AIRFLOW_CTX_EXECUTION_DATE=2024-02-21T05:48:21.103638+00:00
AIRFLOW_CTX_TRY_NUMBER=1
AIRFLOW_CTX_DAG_RUN_ID=manual__2024-02-21T05:48:21.103638+00:00
[2024-02-21 05:48:23,613] {subprocess.py:62} INFO - Tmp dir root location: 
 /tmp
[2024-02-21 05:48:23,614] {subprocess.py:74} INFO - Running command: ['bash', '-c', 'source /opt/***/dags/venv/bin/activate && pytest /opt/***/dags/tests']
[2024-02-21 05:48:23,622] {subprocess.py:85} INFO - Output:
[2024-02-21 05:48:23,627] {subprocess.py:92} INFO - bash: line 1: pytest: command not found
[2024-02-21 05:48:23,628] {subprocess.py:96} INFO - Command exited with return code 127
[2024-02-21 05:48:23,643] {taskinstance.py:1889} ERROR - Task failed with exception
Traceback (most recent call last):
  File "/home/airflow/.local/lib/python3.7/site-packages/airflow/operators/bash.py", line 195, in execute
    f'Bash command failed. The command returned a non-zero exit code {result.exit_code}.'
airflow.exceptions.AirflowException: Bash command failed. The command returned a non-zero exit code 127.
[2024-02-21 05:48:23,647] {taskinstance.py:1400} INFO - Marking task as UP_FOR_RETRY. dag_id=csv_transformation_and_class_creation, task_id=create_class_task, execution_date=20240221T054821, start_date=20240221T054823, end_date=20240221T054823
[2024-02-21 05:48:23,663] {standard_task_runner.py:97} ERROR - Failed to execute job 37 for task create_class_task (Bash command failed. The command returned a non-zero exit code 127.; 2904)
[2024-02-21 05:48:23,685] {local_task_job.py:156} INFO - Task exited with return code 1
[2024-02-21 05:48:23,711] {local_task_job.py:273} INFO - 0 downstream tasks scheduled from follow-on schedule check
